JavaScript异常处理的方式，统一的异常处理方案

 为何 try里面放 return， finally还会执行，理解其内部机制

## JS能抛出几种类型的错误
1. RangeError
- 当数字超出了允许的值范围时
- 栈溢出
```JAVASCRIPT
// 数字超出了允许的值范围
const arr = [90, 88]
arr.length = 90**99 // Uncaught RangeError: Invalid array length

// 栈溢出
function foo() {
    foo();
}
foo(); // Uncaught RangeError: Maximum call stack size exceeded
```
2. ReferenceError
当对变量/项的引用被破坏时，引发错误。常见于变量/项不存在, 读取null/defined变量的属性
```javascript
const cat = null;
console.log(cat.name) // Uncaught ReferenceError： dog is not defined
```

3. SyntaxError
语法错误，输入了JS引擎无法理解的代码时，报错
```javascript
let cat h = 'cat' // Uncaught ReferenceError： dog is not defined
```

4. TypeError
对错误的数据类型执行操作时，会发生类型错误。
```javascript
const num = 23;
num.toUpperCase(); // Uncaught TypeError： num.toUpperCase is not a function
```

5. URIError
decodeURI, decodeURIComponent等，如果用错误的参数调用这些API，会得到一个URIError
```javascript
decodeURI("%") // Uncaught URIError： URI malformed
```